2022-08-18 15:01:12,719 INFO    MainThread:10876 [wandb_setup.py:_flush():76] Configure stats pid to 10876
2022-08-18 15:01:12,719 INFO    MainThread:10876 [wandb_setup.py:_flush():76] Loading settings from C:\Users\user\.config\wandb\settings
2022-08-18 15:01:12,719 INFO    MainThread:10876 [wandb_setup.py:_flush():76] Loading settings from c:\Users\user\OneDrive\문서\NLP\base_line_transformer\wandb\settings
2022-08-18 15:01:12,719 INFO    MainThread:10876 [wandb_setup.py:_flush():76] Loading settings from environment variables: {'_require_service': 'True', 'mode': 'online'}
2022-08-18 15:01:12,719 INFO    MainThread:10876 [wandb_setup.py:_flush():76] Inferring run settings from compute environment: {'program': '<python with no main file>'}
2022-08-18 15:01:12,719 INFO    MainThread:10876 [wandb_setup.py:_flush():76] Applying login settings: {'api_key': '***REDACTED***'}
2022-08-18 15:01:12,720 INFO    MainThread:10876 [wandb_init.py:_log_setup():461] Logging user logs to c:\Users\user\OneDrive\문서\NLP\base_line_transformer\wandb\run-20220818_150112-33cz6nly\logs\debug.log
2022-08-18 15:01:12,720 INFO    MainThread:10876 [wandb_init.py:_log_setup():462] Logging internal logs to c:\Users\user\OneDrive\문서\NLP\base_line_transformer\wandb\run-20220818_150112-33cz6nly\logs\debug-internal.log
2022-08-18 15:01:12,720 INFO    MainThread:10876 [wandb_init.py:init():495] calling init triggers
2022-08-18 15:01:12,720 INFO    MainThread:10876 [wandb_init.py:init():498] wandb.init called with sweep_config: {}
config: {'VOCAB_SIZE': 10000, 'SEQ_LEN': 60, 'N': 2, 'HIDDEN_DIM': 256, 'NUM_HEAD': 8, 'INNER_DIM': 512, 'BATCH_SIZE': 64, 'WEIGHT_DECAY': 0, 'LEARNING_RATE': 0.0001}
2022-08-18 15:01:12,720 INFO    MainThread:10876 [wandb_init.py:init():548] starting backend
2022-08-18 15:01:12,720 INFO    MainThread:10876 [wandb_init.py:init():552] setting up manager
2022-08-18 15:01:12,744 ERROR   MainThread:10876 [wandb_init.py:init():1070] error
Traceback (most recent call last):
  File "c:\Users\user\anaconda3\envs\for_wdb\lib\site-packages\wandb\sdk\wandb_init.py", line 1043, in init
    run = wi.init()
  File "c:\Users\user\anaconda3\envs\for_wdb\lib\site-packages\wandb\sdk\wandb_init.py", line 553, in init
    manager._inform_init(settings=self.settings, run_id=self.settings.run_id)
  File "c:\Users\user\anaconda3\envs\for_wdb\lib\site-packages\wandb\sdk\wandb_manager.py", line 161, in _inform_init
    svc_iface._svc_inform_init(settings=settings, run_id=run_id)
  File "c:\Users\user\anaconda3\envs\for_wdb\lib\site-packages\wandb\sdk\service\service_sock.py", line 39, in _svc_inform_init
    self._sock_client.send(inform_init=inform_init)
  File "c:\Users\user\anaconda3\envs\for_wdb\lib\site-packages\wandb\sdk\lib\sock_client.py", line 140, in send
    self.send_server_request(server_req)
  File "c:\Users\user\anaconda3\envs\for_wdb\lib\site-packages\wandb\sdk\lib\sock_client.py", line 84, in send_server_request
    self._send_message(msg)
  File "c:\Users\user\anaconda3\envs\for_wdb\lib\site-packages\wandb\sdk\lib\sock_client.py", line 81, in _send_message
    self._sendall_with_error_handle(header + data)
  File "c:\Users\user\anaconda3\envs\for_wdb\lib\site-packages\wandb\sdk\lib\sock_client.py", line 61, in _sendall_with_error_handle
    sent = self._sock.send(data[total_sent:])
ConnectionResetError: [WinError 10054] 현재 연결은 원격 호스트에 의해 강제로 끊겼습니다
